  0%|                                                                                                                                                                                  | 0/1860 [00:00<?, ?it/s]Traceback (most recent call last):
  File "/home/zl3466/Documents/cmu/10623/proj/train.py", line 123, in <module>
    main()
  File "/home/zl3466/Documents/cmu/10623/proj/train.py", line 118, in main
    trainer.train()
  File "/home/zl3466/Documents/cmu/10623/proj/src/vo_trainer.py", line 255, in train
    trainer.train()
  File "/home/zl3466/anaconda3/envs/voformer/lib/python3.9/site-packages/transformers/trainer.py", line 2325, in train
    return inner_training_loop(
  File "/home/zl3466/anaconda3/envs/voformer/lib/python3.9/site-packages/transformers/trainer.py", line 2674, in _inner_training_loop
    tr_loss_step = self.training_step(model, inputs, num_items_in_batch)
  File "/home/zl3466/anaconda3/envs/voformer/lib/python3.9/site-packages/transformers/trainer.py", line 4020, in training_step
    loss = self.compute_loss(model, inputs, num_items_in_batch=num_items_in_batch)
TypeError: compute_loss() got an unexpected keyword argument 'num_items_in_batch'
